2022-04-02 17:21:47	jobqueue_worker	INFO	/Users/mario/Documents/Projects/intent-service/venv/lib/python3.9/site-packages/jobqueue_worker/worker.py|304	Claim almost expired, retrieving new configuration
2022-04-02 17:21:47	jobqueue_worker	INFO	/Users/mario/Documents/Projects/intent-service/venv/lib/python3.9/site-packages/jobqueue_worker/services/jobqueue_service.py|26	Changed setting 'AZURE_STORAGE_ACCOUNT_CONTAINER_INP' to 'jobinputs'
2022-04-02 17:21:47	jobqueue_worker	INFO	/Users/mario/Documents/Projects/intent-service/venv/lib/python3.9/site-packages/jobqueue_worker/services/jobqueue_service.py|34	Changed setting 'AZURE_STORAGE_ACCOUNT_CONTAINER_OUT' to 'jobresults'
2022-04-02 17:21:47	jobqueue_worker	INFO	/Users/mario/Documents/Projects/intent-service/venv/lib/python3.9/site-packages/jobqueue_worker/services/jobqueue_service.py|42	Changed setting 'AZURE_STORAGE_ACCOUNT_PARTITION_KEY' to 'jobs'
2022-04-02 17:21:47	jobqueue_worker	INFO	/Users/mario/Documents/Projects/intent-service/venv/lib/python3.9/site-packages/jobqueue_worker/services/jobqueue_service.py|48	Changed setting 'AZURE_STORAGE_ACCOUNT_TABLE' to 'jobs01'
2022-04-02 17:21:47	jobqueue_worker	INFO	/Users/mario/Documents/Projects/intent-service/venv/lib/python3.9/site-packages/jobqueue_worker/services/jobqueue_service.py|54	Changed setting 'AZURE_STORAGE_ACCOUNT_NAME' to 'triaiqueuexdevweeustg0'
2022-04-02 17:21:47	jobqueue_worker	INFO	/Users/mario/Documents/Projects/intent-service/venv/lib/python3.9/site-packages/jobqueue_worker/services/jobqueue_service.py|60	Changed setting 'AZURE_STORAGE_ACCOUNT_KEY'
2022-04-02 17:21:47	jobqueue_worker	INFO	/Users/mario/Documents/Projects/intent-service/venv/lib/python3.9/site-packages/jobqueue_worker/worker.py|30	Current sas token is valid until 2022-04-02T23:21:47Z
2022-04-02 17:21:47	jobqueue_worker	INFO	/Users/mario/Documents/Projects/intent-service/venv/lib/python3.9/site-packages/jobqueue_worker/worker.py|287	retry wait: 60
2022-04-02 18:06:34	jobqueue_worker	INFO	/Users/mario/Documents/Projects/intent-service/venv/lib/python3.9/site-packages/jobqueue_worker/worker.py|287	retry wait: 60
2022-04-02 18:24:47	jobqueue_worker	INFO	/Users/mario/Documents/Projects/intent-service/venv/lib/python3.9/site-packages/jobqueue_worker/worker.py|287	retry wait: 60
2022-04-02 18:25:47	jobqueue_worker	INFO	/Users/mario/Documents/Projects/intent-service/venv/lib/python3.9/site-packages/jobqueue_worker/worker.py|287	retry wait: 60
2022-04-02 18:26:47	jobqueue_worker	INFO	/Users/mario/Documents/Projects/intent-service/venv/lib/python3.9/site-packages/jobqueue_worker/worker.py|287	retry wait: 60
2022-04-02 18:27:47	jobqueue_worker	INFO	/Users/mario/Documents/Projects/intent-service/venv/lib/python3.9/site-packages/jobqueue_worker/worker.py|287	retry wait: 60
2022-04-02 18:28:48	jobqueue_worker	INFO	/Users/mario/Documents/Projects/intent-service/venv/lib/python3.9/site-packages/jobqueue_worker/worker.py|287	retry wait: 60
2022-04-02 18:29:48	jobqueue_worker	INFO	/Users/mario/Documents/Projects/intent-service/venv/lib/python3.9/site-packages/jobqueue_worker/worker.py|287	retry wait: 60
2022-04-02 18:30:48	jobqueue_worker	INFO	/Users/mario/Documents/Projects/intent-service/venv/lib/python3.9/site-packages/jobqueue_worker/worker.py|287	retry wait: 60
2022-04-02 18:31:48	jobqueue_worker	INFO	/Users/mario/Documents/Projects/intent-service/venv/lib/python3.9/site-packages/jobqueue_worker/worker.py|287	retry wait: 60
2022-04-02 18:32:48	jobqueue_worker	INFO	/Users/mario/Documents/Projects/intent-service/venv/lib/python3.9/site-packages/jobqueue_worker/worker.py|287	retry wait: 60
2022-04-02 18:33:49	jobqueue_worker	INFO	/Users/mario/Documents/Projects/intent-service/venv/lib/python3.9/site-packages/jobqueue_worker/worker.py|287	retry wait: 60
2022-04-02 18:34:49	jobqueue_worker	INFO	/Users/mario/Documents/Projects/intent-service/venv/lib/python3.9/site-packages/jobqueue_worker/worker.py|287	retry wait: 60
2022-04-02 18:35:49	jobqueue_worker	INFO	/Users/mario/Documents/Projects/intent-service/venv/lib/python3.9/site-packages/jobqueue_worker/worker.py|287	retry wait: 60
2022-04-02 18:36:52	jobqueue_worker	INFO	/Users/mario/Documents/Projects/intent-service/venv/lib/python3.9/site-packages/jobqueue_worker/worker.py|287	retry wait: 60
2022-04-02 18:37:52	jobqueue_worker	INFO	/Users/mario/Documents/Projects/intent-service/venv/lib/python3.9/site-packages/jobqueue_worker/worker.py|287	retry wait: 60
2022-04-02 18:38:52	jobqueue_worker	INFO	/Users/mario/Documents/Projects/intent-service/venv/lib/python3.9/site-packages/jobqueue_worker/worker.py|287	retry wait: 60
2022-04-02 18:39:53	jobqueue_worker	INFO	/Users/mario/Documents/Projects/intent-service/venv/lib/python3.9/site-packages/jobqueue_worker/worker.py|287	retry wait: 60
2022-04-02 18:40:53	jobqueue_worker	INFO	/Users/mario/Documents/Projects/intent-service/venv/lib/python3.9/site-packages/jobqueue_worker/worker.py|287	retry wait: 60
2022-04-02 18:41:53	jobqueue_worker	INFO	/Users/mario/Documents/Projects/intent-service/venv/lib/python3.9/site-packages/jobqueue_worker/worker.py|287	retry wait: 60
2022-04-02 18:42:53	jobqueue_worker	INFO	/Users/mario/Documents/Projects/intent-service/venv/lib/python3.9/site-packages/jobqueue_worker/worker.py|287	retry wait: 60
2022-04-02 18:43:53	jobqueue_worker	INFO	/Users/mario/Documents/Projects/intent-service/venv/lib/python3.9/site-packages/jobqueue_worker/worker.py|287	retry wait: 60
2022-04-02 18:44:54	jobqueue_worker	INFO	/Users/mario/Documents/Projects/intent-service/venv/lib/python3.9/site-packages/jobqueue_worker/worker.py|287	retry wait: 60
2022-04-02 18:45:54	jobqueue_worker	INFO	/Users/mario/Documents/Projects/intent-service/venv/lib/python3.9/site-packages/jobqueue_worker/worker.py|287	retry wait: 60
2022-04-02 18:46:54	jobqueue_worker	INFO	/Users/mario/Documents/Projects/intent-service/venv/lib/python3.9/site-packages/jobqueue_worker/worker.py|287	retry wait: 60
2022-04-02 18:47:54	jobqueue_worker	INFO	/Users/mario/Documents/Projects/intent-service/venv/lib/python3.9/site-packages/jobqueue_worker/worker.py|287	retry wait: 60
2022-04-02 18:48:54	jobqueue_worker	INFO	/Users/mario/Documents/Projects/intent-service/venv/lib/python3.9/site-packages/jobqueue_worker/worker.py|287	retry wait: 60
2022-04-02 18:49:55	jobqueue_worker	INFO	/Users/mario/Documents/Projects/intent-service/venv/lib/python3.9/site-packages/jobqueue_worker/worker.py|287	retry wait: 60
2022-04-02 18:50:55	jobqueue_worker	INFO	/Users/mario/Documents/Projects/intent-service/venv/lib/python3.9/site-packages/jobqueue_worker/worker.py|287	retry wait: 60
2022-04-02 18:51:55	jobqueue_worker	INFO	/Users/mario/Documents/Projects/intent-service/venv/lib/python3.9/site-packages/jobqueue_worker/worker.py|287	retry wait: 60
2022-04-02 18:52:55	jobqueue_worker	INFO	/Users/mario/Documents/Projects/intent-service/venv/lib/python3.9/site-packages/jobqueue_worker/worker.py|287	retry wait: 60
2022-04-02 18:53:55	jobqueue_worker	INFO	/Users/mario/Documents/Projects/intent-service/venv/lib/python3.9/site-packages/jobqueue_worker/worker.py|287	retry wait: 60
2022-04-02 18:54:55	jobqueue_worker	INFO	/Users/mario/Documents/Projects/intent-service/venv/lib/python3.9/site-packages/jobqueue_worker/worker.py|287	retry wait: 60
2022-04-02 18:55:56	jobqueue_worker	INFO	/Users/mario/Documents/Projects/intent-service/venv/lib/python3.9/site-packages/jobqueue_worker/worker.py|287	retry wait: 60
2022-04-02 18:56:56	jobqueue_worker	INFO	/Users/mario/Documents/Projects/intent-service/venv/lib/python3.9/site-packages/jobqueue_worker/worker.py|287	retry wait: 60
2022-04-02 18:57:56	jobqueue_worker	INFO	/Users/mario/Documents/Projects/intent-service/venv/lib/python3.9/site-packages/jobqueue_worker/worker.py|287	retry wait: 60
2022-04-02 18:58:57	jobqueue_worker	INFO	/Users/mario/Documents/Projects/intent-service/venv/lib/python3.9/site-packages/jobqueue_worker/worker.py|287	retry wait: 60
2022-04-02 18:59:57	jobqueue_worker	INFO	/Users/mario/Documents/Projects/intent-service/venv/lib/python3.9/site-packages/jobqueue_worker/worker.py|287	retry wait: 60
2022-04-02 19:00:57	jobqueue_worker	INFO	/Users/mario/Documents/Projects/intent-service/venv/lib/python3.9/site-packages/jobqueue_worker/worker.py|287	retry wait: 60
2022-04-02 19:01:57	jobqueue_worker	INFO	/Users/mario/Documents/Projects/intent-service/venv/lib/python3.9/site-packages/jobqueue_worker/worker.py|287	retry wait: 60
2022-04-02 19:02:58	jobqueue_worker	INFO	/Users/mario/Documents/Projects/intent-service/venv/lib/python3.9/site-packages/jobqueue_worker/worker.py|287	retry wait: 60
2022-04-02 19:03:58	jobqueue_worker	INFO	/Users/mario/Documents/Projects/intent-service/venv/lib/python3.9/site-packages/jobqueue_worker/worker.py|287	retry wait: 60
2022-04-02 19:08:24	jobqueue_worker	INFO	/Users/mario/Documents/Projects/intent-service/venv/lib/python3.9/site-packages/jobqueue_worker/worker.py|287	retry wait: 60
2022-04-02 19:09:24	jobqueue_worker	INFO	/Users/mario/Documents/Projects/intent-service/venv/lib/python3.9/site-packages/jobqueue_worker/worker.py|287	retry wait: 60
2022-04-02 19:10:39	jobqueue_worker	INFO	/Users/mario/Documents/Projects/intent-service/venv/lib/python3.9/site-packages/jobqueue_worker/worker.py|287	retry wait: 60
2022-04-02 19:11:39	jobqueue_worker	INFO	/Users/mario/Documents/Projects/intent-service/venv/lib/python3.9/site-packages/jobqueue_worker/worker.py|287	retry wait: 60
2022-04-02 19:12:40	jobqueue_worker	INFO	/Users/mario/Documents/Projects/intent-service/venv/lib/python3.9/site-packages/jobqueue_worker/worker.py|287	retry wait: 60
2022-04-02 19:13:40	jobqueue_worker	INFO	/Users/mario/Documents/Projects/intent-service/venv/lib/python3.9/site-packages/jobqueue_worker/worker.py|287	retry wait: 60
2022-04-02 19:14:40	jobqueue_worker	INFO	/Users/mario/Documents/Projects/intent-service/venv/lib/python3.9/site-packages/jobqueue_worker/worker.py|287	retry wait: 60
2022-04-02 19:15:40	jobqueue_worker	INFO	/Users/mario/Documents/Projects/intent-service/venv/lib/python3.9/site-packages/jobqueue_worker/worker.py|287	retry wait: 60
2022-04-02 19:16:40	jobqueue_worker	INFO	/Users/mario/Documents/Projects/intent-service/venv/lib/python3.9/site-packages/jobqueue_worker/worker.py|287	retry wait: 60
2022-04-02 19:17:41	jobqueue_worker	INFO	/Users/mario/Documents/Projects/intent-service/venv/lib/python3.9/site-packages/jobqueue_worker/worker.py|287	retry wait: 60
2022-04-02 19:18:41	jobqueue_worker	INFO	/Users/mario/Documents/Projects/intent-service/venv/lib/python3.9/site-packages/jobqueue_worker/worker.py|287	retry wait: 60
2022-04-02 19:19:41	jobqueue_worker	INFO	/Users/mario/Documents/Projects/intent-service/venv/lib/python3.9/site-packages/jobqueue_worker/worker.py|287	retry wait: 60
2022-04-02 19:20:41	jobqueue_worker	INFO	/Users/mario/Documents/Projects/intent-service/venv/lib/python3.9/site-packages/jobqueue_worker/worker.py|287	retry wait: 60
2022-04-02 19:21:41	jobqueue_worker	INFO	/Users/mario/Documents/Projects/intent-service/venv/lib/python3.9/site-packages/jobqueue_worker/worker.py|287	retry wait: 60
2022-04-02 19:22:41	jobqueue_worker	INFO	/Users/mario/Documents/Projects/intent-service/venv/lib/python3.9/site-packages/jobqueue_worker/worker.py|287	retry wait: 60
2022-04-02 19:23:42	jobqueue_worker	INFO	/Users/mario/Documents/Projects/intent-service/venv/lib/python3.9/site-packages/jobqueue_worker/worker.py|287	retry wait: 60
2022-04-02 19:24:42	jobqueue_worker	INFO	/Users/mario/Documents/Projects/intent-service/venv/lib/python3.9/site-packages/jobqueue_worker/worker.py|287	retry wait: 60
2022-04-02 19:25:42	jobqueue_worker	INFO	/Users/mario/Documents/Projects/intent-service/venv/lib/python3.9/site-packages/jobqueue_worker/worker.py|287	retry wait: 60
2022-04-02 19:26:42	jobqueue_worker	INFO	/Users/mario/Documents/Projects/intent-service/venv/lib/python3.9/site-packages/jobqueue_worker/worker.py|287	retry wait: 60
2022-04-02 19:27:42	jobqueue_worker	INFO	/Users/mario/Documents/Projects/intent-service/venv/lib/python3.9/site-packages/jobqueue_worker/worker.py|287	retry wait: 60
2022-04-02 19:28:43	jobqueue_worker	INFO	/Users/mario/Documents/Projects/intent-service/venv/lib/python3.9/site-packages/jobqueue_worker/worker.py|287	retry wait: 60
2022-04-02 19:29:43	jobqueue_worker	INFO	/Users/mario/Documents/Projects/intent-service/venv/lib/python3.9/site-packages/jobqueue_worker/worker.py|287	retry wait: 60
2022-04-02 19:30:43	jobqueue_worker	INFO	/Users/mario/Documents/Projects/intent-service/venv/lib/python3.9/site-packages/jobqueue_worker/worker.py|287	retry wait: 60
2022-04-02 19:31:43	jobqueue_worker	INFO	/Users/mario/Documents/Projects/intent-service/venv/lib/python3.9/site-packages/jobqueue_worker/worker.py|287	retry wait: 60
2022-04-02 19:32:43	jobqueue_worker	INFO	/Users/mario/Documents/Projects/intent-service/venv/lib/python3.9/site-packages/jobqueue_worker/worker.py|287	retry wait: 60
2022-04-02 19:33:43	jobqueue_worker	INFO	/Users/mario/Documents/Projects/intent-service/venv/lib/python3.9/site-packages/jobqueue_worker/worker.py|287	retry wait: 60
2022-04-02 19:34:44	jobqueue_worker	INFO	/Users/mario/Documents/Projects/intent-service/venv/lib/python3.9/site-packages/jobqueue_worker/worker.py|287	retry wait: 60
2022-04-02 19:35:44	jobqueue_worker	INFO	/Users/mario/Documents/Projects/intent-service/venv/lib/python3.9/site-packages/jobqueue_worker/worker.py|287	retry wait: 60
2022-04-02 19:36:44	jobqueue_worker	INFO	/Users/mario/Documents/Projects/intent-service/venv/lib/python3.9/site-packages/jobqueue_worker/worker.py|287	retry wait: 60
2022-04-02 19:37:44	jobqueue_worker	INFO	/Users/mario/Documents/Projects/intent-service/venv/lib/python3.9/site-packages/jobqueue_worker/worker.py|287	retry wait: 60
2022-04-02 19:38:44	jobqueue_worker	INFO	/Users/mario/Documents/Projects/intent-service/venv/lib/python3.9/site-packages/jobqueue_worker/worker.py|287	retry wait: 60
2022-04-02 19:39:44	jobqueue_worker	INFO	/Users/mario/Documents/Projects/intent-service/venv/lib/python3.9/site-packages/jobqueue_worker/worker.py|287	retry wait: 60
2022-04-02 19:40:45	jobqueue_worker	INFO	/Users/mario/Documents/Projects/intent-service/venv/lib/python3.9/site-packages/jobqueue_worker/worker.py|287	retry wait: 60
2022-04-02 19:41:45	jobqueue_worker	INFO	/Users/mario/Documents/Projects/intent-service/venv/lib/python3.9/site-packages/jobqueue_worker/worker.py|287	retry wait: 60
2022-04-02 19:42:45	jobqueue_worker	INFO	/Users/mario/Documents/Projects/intent-service/venv/lib/python3.9/site-packages/jobqueue_worker/worker.py|287	retry wait: 60
2022-04-02 19:43:45	jobqueue_worker	INFO	/Users/mario/Documents/Projects/intent-service/venv/lib/python3.9/site-packages/jobqueue_worker/worker.py|287	retry wait: 60
2022-04-02 19:44:45	jobqueue_worker	INFO	/Users/mario/Documents/Projects/intent-service/venv/lib/python3.9/site-packages/jobqueue_worker/worker.py|287	retry wait: 60
2022-04-02 19:45:46	jobqueue_worker	INFO	/Users/mario/Documents/Projects/intent-service/venv/lib/python3.9/site-packages/jobqueue_worker/worker.py|287	retry wait: 60
2022-04-02 19:46:46	jobqueue_worker	INFO	/Users/mario/Documents/Projects/intent-service/venv/lib/python3.9/site-packages/jobqueue_worker/worker.py|287	retry wait: 60
2022-04-02 20:24:58	jobqueue_worker	INFO	/Users/mario/Documents/Projects/intent-service/venv/lib/python3.9/site-packages/jobqueue_worker/worker.py|287	retry wait: 60
2022-04-02 20:41:58	jobqueue_worker	INFO	/Users/mario/Documents/Projects/intent-service/venv/lib/python3.9/site-packages/jobqueue_worker/worker.py|287	retry wait: 60
2022-04-02 22:15:52	jobqueue_worker	INFO	/Users/mario/Documents/Projects/intent-service/venv/lib/python3.9/site-packages/jobqueue_worker/worker.py|287	retry wait: 60
2022-04-02 23:49:41	jobqueue_worker	INFO	/Users/mario/Documents/Projects/intent-service/venv/lib/python3.9/site-packages/jobqueue_worker/worker.py|287	retry wait: 60
2022-04-03 01:07:17	jobqueue_worker	INFO	/Users/mario/Documents/Projects/intent-service/venv/lib/python3.9/site-packages/jobqueue_worker/worker.py|304	Claim almost expired, retrieving new configuration
2022-04-03 01:07:32	jobqueue_worker	ERROR	/Users/mario/Documents/Projects/intent-service/venv/lib/python3.9/site-packages/jobqueue_worker/worker.py|307	Renewing configuration failed
Traceback (most recent call last):
  File "/Users/mario/Documents/Projects/intent-service/venv/lib/python3.9/site-packages/urllib3/connectionpool.py", line 703, in urlopen
    httplib_response = self._make_request(
  File "/Users/mario/Documents/Projects/intent-service/venv/lib/python3.9/site-packages/urllib3/connectionpool.py", line 449, in _make_request
    six.raise_from(e, None)
  File "<string>", line 3, in raise_from
  File "/Users/mario/Documents/Projects/intent-service/venv/lib/python3.9/site-packages/urllib3/connectionpool.py", line 444, in _make_request
    httplib_response = conn.getresponse()
  File "/opt/homebrew/Cellar/python@3.9/3.9.10/Frameworks/Python.framework/Versions/3.9/lib/python3.9/http/client.py", line 1377, in getresponse
    response.begin()
  File "/opt/homebrew/Cellar/python@3.9/3.9.10/Frameworks/Python.framework/Versions/3.9/lib/python3.9/http/client.py", line 320, in begin
    version, status, reason = self._read_status()
  File "/opt/homebrew/Cellar/python@3.9/3.9.10/Frameworks/Python.framework/Versions/3.9/lib/python3.9/http/client.py", line 281, in _read_status
    line = str(self.fp.readline(_MAXLINE + 1), "iso-8859-1")
  File "/opt/homebrew/Cellar/python@3.9/3.9.10/Frameworks/Python.framework/Versions/3.9/lib/python3.9/socket.py", line 704, in readinto
    return self._sock.recv_into(b)
  File "/opt/homebrew/Cellar/python@3.9/3.9.10/Frameworks/Python.framework/Versions/3.9/lib/python3.9/ssl.py", line 1241, in recv_into
    return self.read(nbytes, buffer)
  File "/opt/homebrew/Cellar/python@3.9/3.9.10/Frameworks/Python.framework/Versions/3.9/lib/python3.9/ssl.py", line 1099, in read
    return self._sslobj.read(len, buffer)
ConnectionResetError: [Errno 54] Connection reset by peer

During handling of the above exception, another exception occurred:

Traceback (most recent call last):
  File "/Users/mario/Documents/Projects/intent-service/venv/lib/python3.9/site-packages/requests/adapters.py", line 440, in send
    resp = conn.urlopen(
  File "/Users/mario/Documents/Projects/intent-service/venv/lib/python3.9/site-packages/urllib3/connectionpool.py", line 785, in urlopen
    retries = retries.increment(
  File "/Users/mario/Documents/Projects/intent-service/venv/lib/python3.9/site-packages/urllib3/util/retry.py", line 550, in increment
    raise six.reraise(type(error), error, _stacktrace)
  File "/Users/mario/Documents/Projects/intent-service/venv/lib/python3.9/site-packages/urllib3/packages/six.py", line 769, in reraise
    raise value.with_traceback(tb)
  File "/Users/mario/Documents/Projects/intent-service/venv/lib/python3.9/site-packages/urllib3/connectionpool.py", line 703, in urlopen
    httplib_response = self._make_request(
  File "/Users/mario/Documents/Projects/intent-service/venv/lib/python3.9/site-packages/urllib3/connectionpool.py", line 449, in _make_request
    six.raise_from(e, None)
  File "<string>", line 3, in raise_from
  File "/Users/mario/Documents/Projects/intent-service/venv/lib/python3.9/site-packages/urllib3/connectionpool.py", line 444, in _make_request
    httplib_response = conn.getresponse()
  File "/opt/homebrew/Cellar/python@3.9/3.9.10/Frameworks/Python.framework/Versions/3.9/lib/python3.9/http/client.py", line 1377, in getresponse
    response.begin()
  File "/opt/homebrew/Cellar/python@3.9/3.9.10/Frameworks/Python.framework/Versions/3.9/lib/python3.9/http/client.py", line 320, in begin
    version, status, reason = self._read_status()
  File "/opt/homebrew/Cellar/python@3.9/3.9.10/Frameworks/Python.framework/Versions/3.9/lib/python3.9/http/client.py", line 281, in _read_status
    line = str(self.fp.readline(_MAXLINE + 1), "iso-8859-1")
  File "/opt/homebrew/Cellar/python@3.9/3.9.10/Frameworks/Python.framework/Versions/3.9/lib/python3.9/socket.py", line 704, in readinto
    return self._sock.recv_into(b)
  File "/opt/homebrew/Cellar/python@3.9/3.9.10/Frameworks/Python.framework/Versions/3.9/lib/python3.9/ssl.py", line 1241, in recv_into
    return self.read(nbytes, buffer)
  File "/opt/homebrew/Cellar/python@3.9/3.9.10/Frameworks/Python.framework/Versions/3.9/lib/python3.9/ssl.py", line 1099, in read
    return self._sslobj.read(len, buffer)
urllib3.exceptions.ProtocolError: ('Connection aborted.', ConnectionResetError(54, 'Connection reset by peer'))

During handling of the above exception, another exception occurred:

Traceback (most recent call last):
  File "/Users/mario/Documents/Projects/intent-service/venv/lib/python3.9/site-packages/jobqueue_worker/worker.py", line 305, in basic_worker
    worker = Worker()
  File "/Users/mario/Documents/Projects/intent-service/venv/lib/python3.9/site-packages/jobqueue_worker/worker.py", line 27, in __init__
    load_configuration()
  File "/Users/mario/Documents/Projects/intent-service/venv/lib/python3.9/site-packages/jobqueue_worker/services/jobqueue_service.py", line 22, in load_configuration
    configuration = get_configuration()
  File "/Users/mario/Documents/Projects/intent-service/venv/lib/python3.9/site-packages/jobqueue_worker/services/jobqueue_service.py", line 15, in get_configuration
    req = requests.get(url, headers=headers)
  File "/Users/mario/Documents/Projects/intent-service/venv/lib/python3.9/site-packages/requests/api.py", line 75, in get
    return request('get', url, params=params, **kwargs)
  File "/Users/mario/Documents/Projects/intent-service/venv/lib/python3.9/site-packages/requests/api.py", line 61, in request
    return session.request(method=method, url=url, **kwargs)
  File "/Users/mario/Documents/Projects/intent-service/venv/lib/python3.9/site-packages/requests/sessions.py", line 529, in request
    resp = self.send(prep, **send_kwargs)
  File "/Users/mario/Documents/Projects/intent-service/venv/lib/python3.9/site-packages/requests/sessions.py", line 645, in send
    r = adapter.send(request, **kwargs)
  File "/Users/mario/Documents/Projects/intent-service/venv/lib/python3.9/site-packages/requests/adapters.py", line 501, in send
    raise ConnectionError(err, request=request)
requests.exceptions.ConnectionError: ('Connection aborted.', ConnectionResetError(54, 'Connection reset by peer'))
2022-04-03 01:07:32	jobqueue_worker	INFO	/Users/mario/Documents/Projects/intent-service/venv/lib/python3.9/site-packages/jobqueue_worker/worker.py|287	retry wait: 60
2022-04-03 02:32:56	jobqueue_worker	INFO	/Users/mario/Documents/Projects/intent-service/venv/lib/python3.9/site-packages/jobqueue_worker/worker.py|304	Claim almost expired, retrieving new configuration
2022-04-03 02:32:57	jobqueue_worker	ERROR	/Users/mario/Documents/Projects/intent-service/venv/lib/python3.9/site-packages/jobqueue_worker/worker.py|307	Renewing configuration failed
Traceback (most recent call last):
  File "/Users/mario/Documents/Projects/intent-service/venv/lib/python3.9/site-packages/jobqueue_worker/worker.py", line 305, in basic_worker
    worker = Worker()
  File "/Users/mario/Documents/Projects/intent-service/venv/lib/python3.9/site-packages/jobqueue_worker/worker.py", line 27, in __init__
    load_configuration()
  File "/Users/mario/Documents/Projects/intent-service/venv/lib/python3.9/site-packages/jobqueue_worker/services/jobqueue_service.py", line 22, in load_configuration
    configuration = get_configuration()
  File "/Users/mario/Documents/Projects/intent-service/venv/lib/python3.9/site-packages/jobqueue_worker/services/jobqueue_service.py", line 18, in get_configuration
    req.raise_for_status()
  File "/Users/mario/Documents/Projects/intent-service/venv/lib/python3.9/site-packages/requests/models.py", line 960, in raise_for_status
    raise HTTPError(http_error_msg, response=self)
requests.exceptions.HTTPError: 401 Client Error: Unauthorized for url: https://ai-connect.wearetriple.com/acc-jobqueue/configuration
2022-04-03 02:32:57	jobqueue_worker	ERROR	/Users/mario/Documents/Projects/intent-service/venv/lib/python3.9/site-packages/jobqueue_worker/worker.py|319	Unauthorized - check azure credentials
Traceback (most recent call last):
  File "/Users/mario/Documents/Projects/intent-service/venv/lib/python3.9/site-packages/azure/storage/queue/_queue_client.py", line 527, in receive_message
    message = self._client.messages.dequeue(
  File "/Users/mario/Documents/Projects/intent-service/venv/lib/python3.9/site-packages/azure/storage/queue/_generated/operations/_messages_operations.py", line 104, in dequeue
    raise models.StorageErrorException(response, self._deserialize)
azure.storage.queue._generated.models._models_py3.StorageErrorException: Operation returned an invalid status 'Server failed to authenticate the request. Make sure the value of Authorization header is formed correctly including the signature.'
Content: <?xml version="1.0" encoding="utf-8"?><Error><Code>AuthenticationFailed</Code><Message>Server failed to authenticate the request. Make sure the value of Authorization header is formed correctly including the signature.
RequestId:aff452f0-0003-0003-20f2-46498b000000
Time:2022-04-03T00:32:57.2111927Z</Message><AuthenticationErrorDetail>Signed expiry time [Sat, 02 Apr 2022 23:21:47 GMT] has to be after signed start time [Sun, 03 Apr 2022 00:32:57 GMT]</AuthenticationErrorDetail></Error>

During handling of the above exception, another exception occurred:

Traceback (most recent call last):
  File "/Users/mario/Documents/Projects/intent-service/venv/lib/python3.9/site-packages/jobqueue_worker/worker.py", line 310, in basic_worker
    job = worker.get_job()
  File "/Users/mario/Documents/Projects/intent-service/venv/lib/python3.9/site-packages/jobqueue_worker/worker.py", line 55, in get_job
    message = self.azure.queue_get(
  File "/Users/mario/Documents/Projects/intent-service/venv/lib/python3.9/site-packages/jobqueue_worker/services/azure_storage_helper.py", line 194, in queue_get
    return queue.receive_message(visibility_timeout=visibility_timeout)
  File "/Users/mario/Documents/Projects/intent-service/venv/lib/python3.9/site-packages/azure/core/tracing/decorator.py", line 73, in wrapper_use_tracer
    return func(*args, **kwargs)
  File "/Users/mario/Documents/Projects/intent-service/venv/lib/python3.9/site-packages/azure/storage/queue/_queue_client.py", line 538, in receive_message
    process_storage_error(error)
  File "/Users/mario/Documents/Projects/intent-service/venv/lib/python3.9/site-packages/azure/storage/queue/_shared/response_handlers.py", line 147, in process_storage_error
    raise error
azure.core.exceptions.ClientAuthenticationError: Server failed to authenticate the request. Make sure the value of Authorization header is formed correctly including the signature.
RequestId:aff452f0-0003-0003-20f2-46498b000000
Time:2022-04-03T00:32:57.2111927Z
ErrorCode:AuthenticationFailed
Error:None
AuthenticationErrorDetail:Signed expiry time [Sat, 02 Apr 2022 23:21:47 GMT] has to be after signed start time [Sun, 03 Apr 2022 00:32:57 GMT]
Content: <?xml version="1.0" encoding="utf-8"?><Error><Code>AuthenticationFailed</Code><Message>Server failed to authenticate the request. Make sure the value of Authorization header is formed correctly including the signature.
RequestId:aff452f0-0003-0003-20f2-46498b000000
Time:2022-04-03T00:32:57.2111927Z</Message><AuthenticationErrorDetail>Signed expiry time [Sat, 02 Apr 2022 23:21:47 GMT] has to be after signed start time [Sun, 03 Apr 2022 00:32:57 GMT]</AuthenticationErrorDetail></Error>
2022-04-03 02:32:57	jobqueue_worker	INFO	/Users/mario/Documents/Projects/intent-service/venv/lib/python3.9/site-packages/jobqueue_worker/worker.py|287	retry wait: 60
2022-04-03 05:18:36	jobqueue_worker	INFO	/Users/mario/Documents/Projects/intent-service/venv/lib/python3.9/site-packages/jobqueue_worker/worker.py|304	Claim almost expired, retrieving new configuration
2022-04-03 05:18:37	jobqueue_worker	ERROR	/Users/mario/Documents/Projects/intent-service/venv/lib/python3.9/site-packages/jobqueue_worker/worker.py|307	Renewing configuration failed
Traceback (most recent call last):
  File "/Users/mario/Documents/Projects/intent-service/venv/lib/python3.9/site-packages/jobqueue_worker/worker.py", line 305, in basic_worker
    worker = Worker()
  File "/Users/mario/Documents/Projects/intent-service/venv/lib/python3.9/site-packages/jobqueue_worker/worker.py", line 27, in __init__
    load_configuration()
  File "/Users/mario/Documents/Projects/intent-service/venv/lib/python3.9/site-packages/jobqueue_worker/services/jobqueue_service.py", line 22, in load_configuration
    configuration = get_configuration()
  File "/Users/mario/Documents/Projects/intent-service/venv/lib/python3.9/site-packages/jobqueue_worker/services/jobqueue_service.py", line 18, in get_configuration
    req.raise_for_status()
  File "/Users/mario/Documents/Projects/intent-service/venv/lib/python3.9/site-packages/requests/models.py", line 960, in raise_for_status
    raise HTTPError(http_error_msg, response=self)
requests.exceptions.HTTPError: 401 Client Error: Unauthorized for url: https://ai-connect.wearetriple.com/acc-jobqueue/configuration
2022-04-03 05:18:37	jobqueue_worker	ERROR	/Users/mario/Documents/Projects/intent-service/venv/lib/python3.9/site-packages/jobqueue_worker/worker.py|319	Unauthorized - check azure credentials
Traceback (most recent call last):
  File "/Users/mario/Documents/Projects/intent-service/venv/lib/python3.9/site-packages/azure/storage/queue/_queue_client.py", line 527, in receive_message
    message = self._client.messages.dequeue(
  File "/Users/mario/Documents/Projects/intent-service/venv/lib/python3.9/site-packages/azure/storage/queue/_generated/operations/_messages_operations.py", line 104, in dequeue
    raise models.StorageErrorException(response, self._deserialize)
azure.storage.queue._generated.models._models_py3.StorageErrorException: Operation returned an invalid status 'Server failed to authenticate the request. Make sure the value of Authorization header is formed correctly including the signature.'
Content: <?xml version="1.0" encoding="utf-8"?><Error><Code>AuthenticationFailed</Code><Message>Server failed to authenticate the request. Make sure the value of Authorization header is formed correctly including the signature.
RequestId:5820bde0-0003-0095-7509-47405a000000
Time:2022-04-03T03:18:37.8113769Z</Message><AuthenticationErrorDetail>Signed expiry time [Sat, 02 Apr 2022 23:21:47 GMT] has to be after signed start time [Sun, 03 Apr 2022 03:18:37 GMT]</AuthenticationErrorDetail></Error>

During handling of the above exception, another exception occurred:

Traceback (most recent call last):
  File "/Users/mario/Documents/Projects/intent-service/venv/lib/python3.9/site-packages/jobqueue_worker/worker.py", line 310, in basic_worker
    job = worker.get_job()
  File "/Users/mario/Documents/Projects/intent-service/venv/lib/python3.9/site-packages/jobqueue_worker/worker.py", line 55, in get_job
    message = self.azure.queue_get(
  File "/Users/mario/Documents/Projects/intent-service/venv/lib/python3.9/site-packages/jobqueue_worker/services/azure_storage_helper.py", line 194, in queue_get
    return queue.receive_message(visibility_timeout=visibility_timeout)
  File "/Users/mario/Documents/Projects/intent-service/venv/lib/python3.9/site-packages/azure/core/tracing/decorator.py", line 73, in wrapper_use_tracer
    return func(*args, **kwargs)
  File "/Users/mario/Documents/Projects/intent-service/venv/lib/python3.9/site-packages/azure/storage/queue/_queue_client.py", line 538, in receive_message
    process_storage_error(error)
  File "/Users/mario/Documents/Projects/intent-service/venv/lib/python3.9/site-packages/azure/storage/queue/_shared/response_handlers.py", line 147, in process_storage_error
    raise error
azure.core.exceptions.ClientAuthenticationError: Server failed to authenticate the request. Make sure the value of Authorization header is formed correctly including the signature.
RequestId:5820bde0-0003-0095-7509-47405a000000
Time:2022-04-03T03:18:37.8113769Z
ErrorCode:AuthenticationFailed
Error:None
AuthenticationErrorDetail:Signed expiry time [Sat, 02 Apr 2022 23:21:47 GMT] has to be after signed start time [Sun, 03 Apr 2022 03:18:37 GMT]
Content: <?xml version="1.0" encoding="utf-8"?><Error><Code>AuthenticationFailed</Code><Message>Server failed to authenticate the request. Make sure the value of Authorization header is formed correctly including the signature.
RequestId:5820bde0-0003-0095-7509-47405a000000
Time:2022-04-03T03:18:37.8113769Z</Message><AuthenticationErrorDetail>Signed expiry time [Sat, 02 Apr 2022 23:21:47 GMT] has to be after signed start time [Sun, 03 Apr 2022 03:18:37 GMT]</AuthenticationErrorDetail></Error>
2022-04-03 05:18:37	jobqueue_worker	INFO	/Users/mario/Documents/Projects/intent-service/venv/lib/python3.9/site-packages/jobqueue_worker/worker.py|287	retry wait: 60
2022-04-03 08:03:27	jobqueue_worker	INFO	/Users/mario/Documents/Projects/intent-service/venv/lib/python3.9/site-packages/jobqueue_worker/worker.py|304	Claim almost expired, retrieving new configuration
2022-04-03 08:03:28	jobqueue_worker	ERROR	/Users/mario/Documents/Projects/intent-service/venv/lib/python3.9/site-packages/jobqueue_worker/worker.py|307	Renewing configuration failed
Traceback (most recent call last):
  File "/Users/mario/Documents/Projects/intent-service/venv/lib/python3.9/site-packages/jobqueue_worker/worker.py", line 305, in basic_worker
    worker = Worker()
  File "/Users/mario/Documents/Projects/intent-service/venv/lib/python3.9/site-packages/jobqueue_worker/worker.py", line 27, in __init__
    load_configuration()
  File "/Users/mario/Documents/Projects/intent-service/venv/lib/python3.9/site-packages/jobqueue_worker/services/jobqueue_service.py", line 22, in load_configuration
    configuration = get_configuration()
  File "/Users/mario/Documents/Projects/intent-service/venv/lib/python3.9/site-packages/jobqueue_worker/services/jobqueue_service.py", line 18, in get_configuration
    req.raise_for_status()
  File "/Users/mario/Documents/Projects/intent-service/venv/lib/python3.9/site-packages/requests/models.py", line 960, in raise_for_status
    raise HTTPError(http_error_msg, response=self)
requests.exceptions.HTTPError: 401 Client Error: Unauthorized for url: https://ai-connect.wearetriple.com/acc-jobqueue/configuration
2022-04-03 08:03:28	jobqueue_worker	ERROR	/Users/mario/Documents/Projects/intent-service/venv/lib/python3.9/site-packages/jobqueue_worker/worker.py|319	Unauthorized - check azure credentials
Traceback (most recent call last):
  File "/Users/mario/Documents/Projects/intent-service/venv/lib/python3.9/site-packages/azure/storage/queue/_queue_client.py", line 527, in receive_message
    message = self._client.messages.dequeue(
  File "/Users/mario/Documents/Projects/intent-service/venv/lib/python3.9/site-packages/azure/storage/queue/_generated/operations/_messages_operations.py", line 104, in dequeue
    raise models.StorageErrorException(response, self._deserialize)
azure.storage.queue._generated.models._models_py3.StorageErrorException: Operation returned an invalid status 'Server failed to authenticate the request. Make sure the value of Authorization header is formed correctly including the signature.'
Content: <?xml version="1.0" encoding="utf-8"?><Error><Code>AuthenticationFailed</Code><Message>Server failed to authenticate the request. Make sure the value of Authorization header is formed correctly including the signature.
RequestId:f9c4557e-f003-004a-7d20-470b60000000
Time:2022-04-03T06:03:28.4106780Z</Message><AuthenticationErrorDetail>Signed expiry time [Sat, 02 Apr 2022 23:21:47 GMT] has to be after signed start time [Sun, 03 Apr 2022 06:03:28 GMT]</AuthenticationErrorDetail></Error>

During handling of the above exception, another exception occurred:

Traceback (most recent call last):
  File "/Users/mario/Documents/Projects/intent-service/venv/lib/python3.9/site-packages/jobqueue_worker/worker.py", line 310, in basic_worker
    job = worker.get_job()
  File "/Users/mario/Documents/Projects/intent-service/venv/lib/python3.9/site-packages/jobqueue_worker/worker.py", line 55, in get_job
    message = self.azure.queue_get(
  File "/Users/mario/Documents/Projects/intent-service/venv/lib/python3.9/site-packages/jobqueue_worker/services/azure_storage_helper.py", line 194, in queue_get
    return queue.receive_message(visibility_timeout=visibility_timeout)
  File "/Users/mario/Documents/Projects/intent-service/venv/lib/python3.9/site-packages/azure/core/tracing/decorator.py", line 73, in wrapper_use_tracer
    return func(*args, **kwargs)
  File "/Users/mario/Documents/Projects/intent-service/venv/lib/python3.9/site-packages/azure/storage/queue/_queue_client.py", line 538, in receive_message
    process_storage_error(error)
  File "/Users/mario/Documents/Projects/intent-service/venv/lib/python3.9/site-packages/azure/storage/queue/_shared/response_handlers.py", line 147, in process_storage_error
    raise error
azure.core.exceptions.ClientAuthenticationError: Server failed to authenticate the request. Make sure the value of Authorization header is formed correctly including the signature.
RequestId:f9c4557e-f003-004a-7d20-470b60000000
Time:2022-04-03T06:03:28.4106780Z
ErrorCode:AuthenticationFailed
Error:None
AuthenticationErrorDetail:Signed expiry time [Sat, 02 Apr 2022 23:21:47 GMT] has to be after signed start time [Sun, 03 Apr 2022 06:03:28 GMT]
Content: <?xml version="1.0" encoding="utf-8"?><Error><Code>AuthenticationFailed</Code><Message>Server failed to authenticate the request. Make sure the value of Authorization header is formed correctly including the signature.
RequestId:f9c4557e-f003-004a-7d20-470b60000000
Time:2022-04-03T06:03:28.4106780Z</Message><AuthenticationErrorDetail>Signed expiry time [Sat, 02 Apr 2022 23:21:47 GMT] has to be after signed start time [Sun, 03 Apr 2022 06:03:28 GMT]</AuthenticationErrorDetail></Error>
2022-04-03 08:03:28	jobqueue_worker	INFO	/Users/mario/Documents/Projects/intent-service/venv/lib/python3.9/site-packages/jobqueue_worker/worker.py|287	retry wait: 60
2022-04-03 10:53:58	jobqueue_worker	INFO	/Users/mario/Documents/Projects/intent-service/venv/lib/python3.9/site-packages/jobqueue_worker/worker.py|304	Claim almost expired, retrieving new configuration
2022-04-03 10:53:59	jobqueue_worker	ERROR	/Users/mario/Documents/Projects/intent-service/venv/lib/python3.9/site-packages/jobqueue_worker/worker.py|307	Renewing configuration failed
Traceback (most recent call last):
  File "/Users/mario/Documents/Projects/intent-service/venv/lib/python3.9/site-packages/jobqueue_worker/worker.py", line 305, in basic_worker
    worker = Worker()
  File "/Users/mario/Documents/Projects/intent-service/venv/lib/python3.9/site-packages/jobqueue_worker/worker.py", line 27, in __init__
    load_configuration()
  File "/Users/mario/Documents/Projects/intent-service/venv/lib/python3.9/site-packages/jobqueue_worker/services/jobqueue_service.py", line 22, in load_configuration
    configuration = get_configuration()
  File "/Users/mario/Documents/Projects/intent-service/venv/lib/python3.9/site-packages/jobqueue_worker/services/jobqueue_service.py", line 18, in get_configuration
    req.raise_for_status()
  File "/Users/mario/Documents/Projects/intent-service/venv/lib/python3.9/site-packages/requests/models.py", line 960, in raise_for_status
    raise HTTPError(http_error_msg, response=self)
requests.exceptions.HTTPError: 401 Client Error: Unauthorized for url: https://ai-connect.wearetriple.com/acc-jobqueue/configuration
2022-04-03 10:53:59	jobqueue_worker	ERROR	/Users/mario/Documents/Projects/intent-service/venv/lib/python3.9/site-packages/jobqueue_worker/worker.py|319	Unauthorized - check azure credentials
Traceback (most recent call last):
  File "/Users/mario/Documents/Projects/intent-service/venv/lib/python3.9/site-packages/azure/storage/queue/_queue_client.py", line 527, in receive_message
    message = self._client.messages.dequeue(
  File "/Users/mario/Documents/Projects/intent-service/venv/lib/python3.9/site-packages/azure/storage/queue/_generated/operations/_messages_operations.py", line 104, in dequeue
    raise models.StorageErrorException(response, self._deserialize)
azure.storage.queue._generated.models._models_py3.StorageErrorException: Operation returned an invalid status 'Server failed to authenticate the request. Make sure the value of Authorization header is formed correctly including the signature.'
Content: <?xml version="1.0" encoding="utf-8"?><Error><Code>AuthenticationFailed</Code><Message>Server failed to authenticate the request. Make sure the value of Authorization header is formed correctly including the signature.
RequestId:25866929-c003-008a-7038-47f35e000000
Time:2022-04-03T08:53:59.3349564Z</Message><AuthenticationErrorDetail>Signed expiry time [Sat, 02 Apr 2022 23:21:47 GMT] has to be after signed start time [Sun, 03 Apr 2022 08:53:59 GMT]</AuthenticationErrorDetail></Error>

During handling of the above exception, another exception occurred:

Traceback (most recent call last):
  File "/Users/mario/Documents/Projects/intent-service/venv/lib/python3.9/site-packages/jobqueue_worker/worker.py", line 310, in basic_worker
    job = worker.get_job()
  File "/Users/mario/Documents/Projects/intent-service/venv/lib/python3.9/site-packages/jobqueue_worker/worker.py", line 55, in get_job
    message = self.azure.queue_get(
  File "/Users/mario/Documents/Projects/intent-service/venv/lib/python3.9/site-packages/jobqueue_worker/services/azure_storage_helper.py", line 194, in queue_get
    return queue.receive_message(visibility_timeout=visibility_timeout)
  File "/Users/mario/Documents/Projects/intent-service/venv/lib/python3.9/site-packages/azure/core/tracing/decorator.py", line 73, in wrapper_use_tracer
    return func(*args, **kwargs)
  File "/Users/mario/Documents/Projects/intent-service/venv/lib/python3.9/site-packages/azure/storage/queue/_queue_client.py", line 538, in receive_message
    process_storage_error(error)
  File "/Users/mario/Documents/Projects/intent-service/venv/lib/python3.9/site-packages/azure/storage/queue/_shared/response_handlers.py", line 147, in process_storage_error
    raise error
azure.core.exceptions.ClientAuthenticationError: Server failed to authenticate the request. Make sure the value of Authorization header is formed correctly including the signature.
RequestId:25866929-c003-008a-7038-47f35e000000
Time:2022-04-03T08:53:59.3349564Z
ErrorCode:AuthenticationFailed
Error:None
AuthenticationErrorDetail:Signed expiry time [Sat, 02 Apr 2022 23:21:47 GMT] has to be after signed start time [Sun, 03 Apr 2022 08:53:59 GMT]
Content: <?xml version="1.0" encoding="utf-8"?><Error><Code>AuthenticationFailed</Code><Message>Server failed to authenticate the request. Make sure the value of Authorization header is formed correctly including the signature.
RequestId:25866929-c003-008a-7038-47f35e000000
Time:2022-04-03T08:53:59.3349564Z</Message><AuthenticationErrorDetail>Signed expiry time [Sat, 02 Apr 2022 23:21:47 GMT] has to be after signed start time [Sun, 03 Apr 2022 08:53:59 GMT]</AuthenticationErrorDetail></Error>
2022-04-03 10:53:59	jobqueue_worker	INFO	/Users/mario/Documents/Projects/intent-service/venv/lib/python3.9/site-packages/jobqueue_worker/worker.py|287	retry wait: 60
2022-04-03 13:25:19	jobqueue_worker	INFO	/Users/mario/Documents/Projects/intent-service/venv/lib/python3.9/site-packages/jobqueue_worker/worker.py|304	Claim almost expired, retrieving new configuration
2022-04-03 13:42:06	jobqueue_worker	ERROR	/Users/mario/Documents/Projects/intent-service/venv/lib/python3.9/site-packages/jobqueue_worker/worker.py|307	Renewing configuration failed
Traceback (most recent call last):
  File "/Users/mario/Documents/Projects/intent-service/venv/lib/python3.9/site-packages/jobqueue_worker/worker.py", line 305, in basic_worker
    worker = Worker()
  File "/Users/mario/Documents/Projects/intent-service/venv/lib/python3.9/site-packages/jobqueue_worker/worker.py", line 27, in __init__
    load_configuration()
  File "/Users/mario/Documents/Projects/intent-service/venv/lib/python3.9/site-packages/jobqueue_worker/services/jobqueue_service.py", line 22, in load_configuration
    configuration = get_configuration()
  File "/Users/mario/Documents/Projects/intent-service/venv/lib/python3.9/site-packages/jobqueue_worker/services/jobqueue_service.py", line 18, in get_configuration
    req.raise_for_status()
  File "/Users/mario/Documents/Projects/intent-service/venv/lib/python3.9/site-packages/requests/models.py", line 960, in raise_for_status
    raise HTTPError(http_error_msg, response=self)
requests.exceptions.HTTPError: 401 Client Error: Unauthorized for url: https://ai-connect.wearetriple.com/acc-jobqueue/configuration
2022-04-03 13:42:07	jobqueue_worker	ERROR	/Users/mario/Documents/Projects/intent-service/venv/lib/python3.9/site-packages/jobqueue_worker/worker.py|319	Unauthorized - check azure credentials
Traceback (most recent call last):
  File "/Users/mario/Documents/Projects/intent-service/venv/lib/python3.9/site-packages/azure/storage/queue/_queue_client.py", line 527, in receive_message
    message = self._client.messages.dequeue(
  File "/Users/mario/Documents/Projects/intent-service/venv/lib/python3.9/site-packages/azure/storage/queue/_generated/operations/_messages_operations.py", line 104, in dequeue
    raise models.StorageErrorException(response, self._deserialize)
azure.storage.queue._generated.models._models_py3.StorageErrorException: Operation returned an invalid status 'Server failed to authenticate the request. Make sure the value of Authorization header is formed correctly including the signature.'
Content: <?xml version="1.0" encoding="utf-8"?><Error><Code>AuthenticationFailed</Code><Message>Server failed to authenticate the request. Make sure the value of Authorization header is formed correctly including the signature.
RequestId:686563cb-d003-0062-4b4f-476ac8000000
Time:2022-04-03T11:42:07.5834249Z</Message><AuthenticationErrorDetail>Signed expiry time [Sat, 02 Apr 2022 23:21:47 GMT] has to be after signed start time [Sun, 03 Apr 2022 11:42:07 GMT]</AuthenticationErrorDetail></Error>

During handling of the above exception, another exception occurred:

Traceback (most recent call last):
  File "/Users/mario/Documents/Projects/intent-service/venv/lib/python3.9/site-packages/jobqueue_worker/worker.py", line 310, in basic_worker
    job = worker.get_job()
  File "/Users/mario/Documents/Projects/intent-service/venv/lib/python3.9/site-packages/jobqueue_worker/worker.py", line 55, in get_job
    message = self.azure.queue_get(
  File "/Users/mario/Documents/Projects/intent-service/venv/lib/python3.9/site-packages/jobqueue_worker/services/azure_storage_helper.py", line 194, in queue_get
    return queue.receive_message(visibility_timeout=visibility_timeout)
  File "/Users/mario/Documents/Projects/intent-service/venv/lib/python3.9/site-packages/azure/core/tracing/decorator.py", line 73, in wrapper_use_tracer
    return func(*args, **kwargs)
  File "/Users/mario/Documents/Projects/intent-service/venv/lib/python3.9/site-packages/azure/storage/queue/_queue_client.py", line 538, in receive_message
    process_storage_error(error)
  File "/Users/mario/Documents/Projects/intent-service/venv/lib/python3.9/site-packages/azure/storage/queue/_shared/response_handlers.py", line 147, in process_storage_error
    raise error
azure.core.exceptions.ClientAuthenticationError: Server failed to authenticate the request. Make sure the value of Authorization header is formed correctly including the signature.
RequestId:686563cb-d003-0062-4b4f-476ac8000000
Time:2022-04-03T11:42:07.5834249Z
ErrorCode:AuthenticationFailed
Error:None
AuthenticationErrorDetail:Signed expiry time [Sat, 02 Apr 2022 23:21:47 GMT] has to be after signed start time [Sun, 03 Apr 2022 11:42:07 GMT]
Content: <?xml version="1.0" encoding="utf-8"?><Error><Code>AuthenticationFailed</Code><Message>Server failed to authenticate the request. Make sure the value of Authorization header is formed correctly including the signature.
RequestId:686563cb-d003-0062-4b4f-476ac8000000
Time:2022-04-03T11:42:07.5834249Z</Message><AuthenticationErrorDetail>Signed expiry time [Sat, 02 Apr 2022 23:21:47 GMT] has to be after signed start time [Sun, 03 Apr 2022 11:42:07 GMT]</AuthenticationErrorDetail></Error>
2022-04-03 13:42:07	jobqueue_worker	INFO	/Users/mario/Documents/Projects/intent-service/venv/lib/python3.9/site-packages/jobqueue_worker/worker.py|202	Retry backoff set to 900 seconds because 5 exception occured
2022-04-03 13:42:07	jobqueue_worker	INFO	/Users/mario/Documents/Projects/intent-service/venv/lib/python3.9/site-packages/jobqueue_worker/worker.py|287	retry wait: 900
2022-04-03 16:20:00	jobqueue_worker	INFO	/Users/mario/Documents/Projects/intent-service/venv/lib/python3.9/site-packages/jobqueue_worker/worker.py|304	Claim almost expired, retrieving new configuration
2022-04-03 16:20:00	jobqueue_worker	ERROR	/Users/mario/Documents/Projects/intent-service/venv/lib/python3.9/site-packages/jobqueue_worker/worker.py|307	Renewing configuration failed
Traceback (most recent call last):
  File "/Users/mario/Documents/Projects/intent-service/venv/lib/python3.9/site-packages/jobqueue_worker/worker.py", line 305, in basic_worker
    worker = Worker()
  File "/Users/mario/Documents/Projects/intent-service/venv/lib/python3.9/site-packages/jobqueue_worker/worker.py", line 27, in __init__
    load_configuration()
  File "/Users/mario/Documents/Projects/intent-service/venv/lib/python3.9/site-packages/jobqueue_worker/services/jobqueue_service.py", line 22, in load_configuration
    configuration = get_configuration()
  File "/Users/mario/Documents/Projects/intent-service/venv/lib/python3.9/site-packages/jobqueue_worker/services/jobqueue_service.py", line 18, in get_configuration
    req.raise_for_status()
  File "/Users/mario/Documents/Projects/intent-service/venv/lib/python3.9/site-packages/requests/models.py", line 960, in raise_for_status
    raise HTTPError(http_error_msg, response=self)
requests.exceptions.HTTPError: 401 Client Error: Unauthorized for url: https://ai-connect.wearetriple.com/acc-jobqueue/configuration
2022-04-03 16:20:00	jobqueue_worker	ERROR	/Users/mario/Documents/Projects/intent-service/venv/lib/python3.9/site-packages/jobqueue_worker/worker.py|319	Unauthorized - check azure credentials
Traceback (most recent call last):
  File "/Users/mario/Documents/Projects/intent-service/venv/lib/python3.9/site-packages/azure/storage/queue/_queue_client.py", line 527, in receive_message
    message = self._client.messages.dequeue(
  File "/Users/mario/Documents/Projects/intent-service/venv/lib/python3.9/site-packages/azure/storage/queue/_generated/operations/_messages_operations.py", line 104, in dequeue
    raise models.StorageErrorException(response, self._deserialize)
azure.storage.queue._generated.models._models_py3.StorageErrorException: Operation returned an invalid status 'Server failed to authenticate the request. Make sure the value of Authorization header is formed correctly including the signature.'
Content: <?xml version="1.0" encoding="utf-8"?><Error><Code>AuthenticationFailed</Code><Message>Server failed to authenticate the request. Make sure the value of Authorization header is formed correctly including the signature.
RequestId:e99926ba-5003-006c-2865-474378000000
Time:2022-04-03T14:20:00.8917213Z</Message><AuthenticationErrorDetail>Signed expiry time [Sat, 02 Apr 2022 23:21:47 GMT] has to be after signed start time [Sun, 03 Apr 2022 14:20:00 GMT]</AuthenticationErrorDetail></Error>

During handling of the above exception, another exception occurred:

Traceback (most recent call last):
  File "/Users/mario/Documents/Projects/intent-service/venv/lib/python3.9/site-packages/jobqueue_worker/worker.py", line 310, in basic_worker
    job = worker.get_job()
  File "/Users/mario/Documents/Projects/intent-service/venv/lib/python3.9/site-packages/jobqueue_worker/worker.py", line 55, in get_job
    message = self.azure.queue_get(
  File "/Users/mario/Documents/Projects/intent-service/venv/lib/python3.9/site-packages/jobqueue_worker/services/azure_storage_helper.py", line 194, in queue_get
    return queue.receive_message(visibility_timeout=visibility_timeout)
  File "/Users/mario/Documents/Projects/intent-service/venv/lib/python3.9/site-packages/azure/core/tracing/decorator.py", line 73, in wrapper_use_tracer
    return func(*args, **kwargs)
  File "/Users/mario/Documents/Projects/intent-service/venv/lib/python3.9/site-packages/azure/storage/queue/_queue_client.py", line 538, in receive_message
    process_storage_error(error)
  File "/Users/mario/Documents/Projects/intent-service/venv/lib/python3.9/site-packages/azure/storage/queue/_shared/response_handlers.py", line 147, in process_storage_error
    raise error
azure.core.exceptions.ClientAuthenticationError: Server failed to authenticate the request. Make sure the value of Authorization header is formed correctly including the signature.
RequestId:e99926ba-5003-006c-2865-474378000000
Time:2022-04-03T14:20:00.8917213Z
ErrorCode:AuthenticationFailed
Error:None
AuthenticationErrorDetail:Signed expiry time [Sat, 02 Apr 2022 23:21:47 GMT] has to be after signed start time [Sun, 03 Apr 2022 14:20:00 GMT]
Content: <?xml version="1.0" encoding="utf-8"?><Error><Code>AuthenticationFailed</Code><Message>Server failed to authenticate the request. Make sure the value of Authorization header is formed correctly including the signature.
RequestId:e99926ba-5003-006c-2865-474378000000
Time:2022-04-03T14:20:00.8917213Z</Message><AuthenticationErrorDetail>Signed expiry time [Sat, 02 Apr 2022 23:21:47 GMT] has to be after signed start time [Sun, 03 Apr 2022 14:20:00 GMT]</AuthenticationErrorDetail></Error>
2022-04-03 16:20:00	jobqueue_worker	INFO	/Users/mario/Documents/Projects/intent-service/venv/lib/python3.9/site-packages/jobqueue_worker/worker.py|202	Retry backoff set to 900 seconds because 6 exception occured
2022-04-03 16:20:00	jobqueue_worker	INFO	/Users/mario/Documents/Projects/intent-service/venv/lib/python3.9/site-packages/jobqueue_worker/worker.py|287	retry wait: 900
2022-04-03 16:35:00	jobqueue_worker	INFO	/Users/mario/Documents/Projects/intent-service/venv/lib/python3.9/site-packages/jobqueue_worker/worker.py|304	Claim almost expired, retrieving new configuration
2022-04-03 16:35:01	jobqueue_worker	ERROR	/Users/mario/Documents/Projects/intent-service/venv/lib/python3.9/site-packages/jobqueue_worker/worker.py|307	Renewing configuration failed
Traceback (most recent call last):
  File "/Users/mario/Documents/Projects/intent-service/venv/lib/python3.9/site-packages/jobqueue_worker/worker.py", line 305, in basic_worker
    worker = Worker()
  File "/Users/mario/Documents/Projects/intent-service/venv/lib/python3.9/site-packages/jobqueue_worker/worker.py", line 27, in __init__
    load_configuration()
  File "/Users/mario/Documents/Projects/intent-service/venv/lib/python3.9/site-packages/jobqueue_worker/services/jobqueue_service.py", line 22, in load_configuration
    configuration = get_configuration()
  File "/Users/mario/Documents/Projects/intent-service/venv/lib/python3.9/site-packages/jobqueue_worker/services/jobqueue_service.py", line 18, in get_configuration
    req.raise_for_status()
  File "/Users/mario/Documents/Projects/intent-service/venv/lib/python3.9/site-packages/requests/models.py", line 960, in raise_for_status
    raise HTTPError(http_error_msg, response=self)
requests.exceptions.HTTPError: 401 Client Error: Unauthorized for url: https://ai-connect.wearetriple.com/acc-jobqueue/configuration
2022-04-03 16:35:01	jobqueue_worker	ERROR	/Users/mario/Documents/Projects/intent-service/venv/lib/python3.9/site-packages/jobqueue_worker/worker.py|319	Unauthorized - check azure credentials
Traceback (most recent call last):
  File "/Users/mario/Documents/Projects/intent-service/venv/lib/python3.9/site-packages/azure/storage/queue/_queue_client.py", line 527, in receive_message
    message = self._client.messages.dequeue(
  File "/Users/mario/Documents/Projects/intent-service/venv/lib/python3.9/site-packages/azure/storage/queue/_generated/operations/_messages_operations.py", line 104, in dequeue
    raise models.StorageErrorException(response, self._deserialize)
azure.storage.queue._generated.models._models_py3.StorageErrorException: Operation returned an invalid status 'Server failed to authenticate the request. Make sure the value of Authorization header is formed correctly including the signature.'
Content: <?xml version="1.0" encoding="utf-8"?><Error><Code>AuthenticationFailed</Code><Message>Server failed to authenticate the request. Make sure the value of Authorization header is formed correctly including the signature.
RequestId:68814e19-d003-0062-0a68-476ac8000000
Time:2022-04-03T14:35:01.2627527Z</Message><AuthenticationErrorDetail>Signed expiry time [Sat, 02 Apr 2022 23:21:47 GMT] has to be after signed start time [Sun, 03 Apr 2022 14:35:01 GMT]</AuthenticationErrorDetail></Error>

During handling of the above exception, another exception occurred:

Traceback (most recent call last):
  File "/Users/mario/Documents/Projects/intent-service/venv/lib/python3.9/site-packages/jobqueue_worker/worker.py", line 310, in basic_worker
    job = worker.get_job()
  File "/Users/mario/Documents/Projects/intent-service/venv/lib/python3.9/site-packages/jobqueue_worker/worker.py", line 55, in get_job
    message = self.azure.queue_get(
  File "/Users/mario/Documents/Projects/intent-service/venv/lib/python3.9/site-packages/jobqueue_worker/services/azure_storage_helper.py", line 194, in queue_get
    return queue.receive_message(visibility_timeout=visibility_timeout)
  File "/Users/mario/Documents/Projects/intent-service/venv/lib/python3.9/site-packages/azure/core/tracing/decorator.py", line 73, in wrapper_use_tracer
    return func(*args, **kwargs)
  File "/Users/mario/Documents/Projects/intent-service/venv/lib/python3.9/site-packages/azure/storage/queue/_queue_client.py", line 538, in receive_message
    process_storage_error(error)
  File "/Users/mario/Documents/Projects/intent-service/venv/lib/python3.9/site-packages/azure/storage/queue/_shared/response_handlers.py", line 147, in process_storage_error
    raise error
azure.core.exceptions.ClientAuthenticationError: Server failed to authenticate the request. Make sure the value of Authorization header is formed correctly including the signature.
RequestId:68814e19-d003-0062-0a68-476ac8000000
Time:2022-04-03T14:35:01.2627527Z
ErrorCode:AuthenticationFailed
Error:None
AuthenticationErrorDetail:Signed expiry time [Sat, 02 Apr 2022 23:21:47 GMT] has to be after signed start time [Sun, 03 Apr 2022 14:35:01 GMT]
Content: <?xml version="1.0" encoding="utf-8"?><Error><Code>AuthenticationFailed</Code><Message>Server failed to authenticate the request. Make sure the value of Authorization header is formed correctly including the signature.
RequestId:68814e19-d003-0062-0a68-476ac8000000
Time:2022-04-03T14:35:01.2627527Z</Message><AuthenticationErrorDetail>Signed expiry time [Sat, 02 Apr 2022 23:21:47 GMT] has to be after signed start time [Sun, 03 Apr 2022 14:35:01 GMT]</AuthenticationErrorDetail></Error>
2022-04-03 16:35:01	jobqueue_worker	INFO	/Users/mario/Documents/Projects/intent-service/venv/lib/python3.9/site-packages/jobqueue_worker/worker.py|202	Retry backoff set to 900 seconds because 7 exception occured
2022-04-03 16:35:01	jobqueue_worker	INFO	/Users/mario/Documents/Projects/intent-service/venv/lib/python3.9/site-packages/jobqueue_worker/worker.py|287	retry wait: 900
2022-04-03 16:50:01	jobqueue_worker	INFO	/Users/mario/Documents/Projects/intent-service/venv/lib/python3.9/site-packages/jobqueue_worker/worker.py|304	Claim almost expired, retrieving new configuration
2022-04-03 16:50:01	jobqueue_worker	ERROR	/Users/mario/Documents/Projects/intent-service/venv/lib/python3.9/site-packages/jobqueue_worker/worker.py|307	Renewing configuration failed
Traceback (most recent call last):
  File "/Users/mario/Documents/Projects/intent-service/venv/lib/python3.9/site-packages/jobqueue_worker/worker.py", line 305, in basic_worker
    worker = Worker()
  File "/Users/mario/Documents/Projects/intent-service/venv/lib/python3.9/site-packages/jobqueue_worker/worker.py", line 27, in __init__
    load_configuration()
  File "/Users/mario/Documents/Projects/intent-service/venv/lib/python3.9/site-packages/jobqueue_worker/services/jobqueue_service.py", line 22, in load_configuration
    configuration = get_configuration()
  File "/Users/mario/Documents/Projects/intent-service/venv/lib/python3.9/site-packages/jobqueue_worker/services/jobqueue_service.py", line 18, in get_configuration
    req.raise_for_status()
  File "/Users/mario/Documents/Projects/intent-service/venv/lib/python3.9/site-packages/requests/models.py", line 960, in raise_for_status
    raise HTTPError(http_error_msg, response=self)
requests.exceptions.HTTPError: 401 Client Error: Unauthorized for url: https://ai-connect.wearetriple.com/acc-jobqueue/configuration
2022-04-03 16:50:01	jobqueue_worker	ERROR	/Users/mario/Documents/Projects/intent-service/venv/lib/python3.9/site-packages/jobqueue_worker/worker.py|319	Unauthorized - check azure credentials
Traceback (most recent call last):
  File "/Users/mario/Documents/Projects/intent-service/venv/lib/python3.9/site-packages/azure/storage/queue/_queue_client.py", line 527, in receive_message
    message = self._client.messages.dequeue(
  File "/Users/mario/Documents/Projects/intent-service/venv/lib/python3.9/site-packages/azure/storage/queue/_generated/operations/_messages_operations.py", line 104, in dequeue
    raise models.StorageErrorException(response, self._deserialize)
azure.storage.queue._generated.models._models_py3.StorageErrorException: Operation returned an invalid status 'Server failed to authenticate the request. Make sure the value of Authorization header is formed correctly including the signature.'
Content: <?xml version="1.0" encoding="utf-8"?><Error><Code>AuthenticationFailed</Code><Message>Server failed to authenticate the request. Make sure the value of Authorization header is formed correctly including the signature.
RequestId:cbca6c94-2003-0004-1e6a-4725e8000000
Time:2022-04-03T14:50:01.9378140Z</Message><AuthenticationErrorDetail>Signed expiry time [Sat, 02 Apr 2022 23:21:47 GMT] has to be after signed start time [Sun, 03 Apr 2022 14:50:01 GMT]</AuthenticationErrorDetail></Error>

During handling of the above exception, another exception occurred:

Traceback (most recent call last):
  File "/Users/mario/Documents/Projects/intent-service/venv/lib/python3.9/site-packages/jobqueue_worker/worker.py", line 310, in basic_worker
    job = worker.get_job()
  File "/Users/mario/Documents/Projects/intent-service/venv/lib/python3.9/site-packages/jobqueue_worker/worker.py", line 55, in get_job
    message = self.azure.queue_get(
  File "/Users/mario/Documents/Projects/intent-service/venv/lib/python3.9/site-packages/jobqueue_worker/services/azure_storage_helper.py", line 194, in queue_get
    return queue.receive_message(visibility_timeout=visibility_timeout)
  File "/Users/mario/Documents/Projects/intent-service/venv/lib/python3.9/site-packages/azure/core/tracing/decorator.py", line 73, in wrapper_use_tracer
    return func(*args, **kwargs)
  File "/Users/mario/Documents/Projects/intent-service/venv/lib/python3.9/site-packages/azure/storage/queue/_queue_client.py", line 538, in receive_message
    process_storage_error(error)
  File "/Users/mario/Documents/Projects/intent-service/venv/lib/python3.9/site-packages/azure/storage/queue/_shared/response_handlers.py", line 147, in process_storage_error
    raise error
azure.core.exceptions.ClientAuthenticationError: Server failed to authenticate the request. Make sure the value of Authorization header is formed correctly including the signature.
RequestId:cbca6c94-2003-0004-1e6a-4725e8000000
Time:2022-04-03T14:50:01.9378140Z
ErrorCode:AuthenticationFailed
Error:None
AuthenticationErrorDetail:Signed expiry time [Sat, 02 Apr 2022 23:21:47 GMT] has to be after signed start time [Sun, 03 Apr 2022 14:50:01 GMT]
Content: <?xml version="1.0" encoding="utf-8"?><Error><Code>AuthenticationFailed</Code><Message>Server failed to authenticate the request. Make sure the value of Authorization header is formed correctly including the signature.
RequestId:cbca6c94-2003-0004-1e6a-4725e8000000
Time:2022-04-03T14:50:01.9378140Z</Message><AuthenticationErrorDetail>Signed expiry time [Sat, 02 Apr 2022 23:21:47 GMT] has to be after signed start time [Sun, 03 Apr 2022 14:50:01 GMT]</AuthenticationErrorDetail></Error>
2022-04-03 16:50:01	jobqueue_worker	INFO	/Users/mario/Documents/Projects/intent-service/venv/lib/python3.9/site-packages/jobqueue_worker/worker.py|202	Retry backoff set to 900 seconds because 8 exception occured
2022-04-03 16:50:01	jobqueue_worker	INFO	/Users/mario/Documents/Projects/intent-service/venv/lib/python3.9/site-packages/jobqueue_worker/worker.py|287	retry wait: 900
2022-04-03 17:12:16	jobqueue_worker	INFO	/Users/mario/Documents/Projects/intent-service/venv/lib/python3.9/site-packages/jobqueue_worker/worker.py|304	Claim almost expired, retrieving new configuration
2022-04-03 17:12:16	jobqueue_worker	ERROR	/Users/mario/Documents/Projects/intent-service/venv/lib/python3.9/site-packages/jobqueue_worker/worker.py|307	Renewing configuration failed
Traceback (most recent call last):
  File "/Users/mario/Documents/Projects/intent-service/venv/lib/python3.9/site-packages/jobqueue_worker/worker.py", line 305, in basic_worker
    worker = Worker()
  File "/Users/mario/Documents/Projects/intent-service/venv/lib/python3.9/site-packages/jobqueue_worker/worker.py", line 27, in __init__
    load_configuration()
  File "/Users/mario/Documents/Projects/intent-service/venv/lib/python3.9/site-packages/jobqueue_worker/services/jobqueue_service.py", line 22, in load_configuration
    configuration = get_configuration()
  File "/Users/mario/Documents/Projects/intent-service/venv/lib/python3.9/site-packages/jobqueue_worker/services/jobqueue_service.py", line 18, in get_configuration
    req.raise_for_status()
  File "/Users/mario/Documents/Projects/intent-service/venv/lib/python3.9/site-packages/requests/models.py", line 960, in raise_for_status
    raise HTTPError(http_error_msg, response=self)
requests.exceptions.HTTPError: 401 Client Error: Unauthorized for url: https://ai-connect.wearetriple.com/acc-jobqueue/configuration
2022-04-03 17:12:16	jobqueue_worker	ERROR	/Users/mario/Documents/Projects/intent-service/venv/lib/python3.9/site-packages/jobqueue_worker/worker.py|319	Unauthorized - check azure credentials
Traceback (most recent call last):
  File "/Users/mario/Documents/Projects/intent-service/venv/lib/python3.9/site-packages/azure/storage/queue/_queue_client.py", line 527, in receive_message
    message = self._client.messages.dequeue(
  File "/Users/mario/Documents/Projects/intent-service/venv/lib/python3.9/site-packages/azure/storage/queue/_generated/operations/_messages_operations.py", line 104, in dequeue
    raise models.StorageErrorException(response, self._deserialize)
azure.storage.queue._generated.models._models_py3.StorageErrorException: Operation returned an invalid status 'Server failed to authenticate the request. Make sure the value of Authorization header is formed correctly including the signature.'
Content: <?xml version="1.0" encoding="utf-8"?><Error><Code>AuthenticationFailed</Code><Message>Server failed to authenticate the request. Make sure the value of Authorization header is formed correctly including the signature.
RequestId:d3c4286f-4003-0070-6f6d-471118000000
Time:2022-04-03T15:12:16.7153607Z</Message><AuthenticationErrorDetail>Signed expiry time [Sat, 02 Apr 2022 23:21:47 GMT] has to be after signed start time [Sun, 03 Apr 2022 15:12:16 GMT]</AuthenticationErrorDetail></Error>

During handling of the above exception, another exception occurred:

Traceback (most recent call last):
  File "/Users/mario/Documents/Projects/intent-service/venv/lib/python3.9/site-packages/jobqueue_worker/worker.py", line 310, in basic_worker
    job = worker.get_job()
  File "/Users/mario/Documents/Projects/intent-service/venv/lib/python3.9/site-packages/jobqueue_worker/worker.py", line 55, in get_job
    message = self.azure.queue_get(
  File "/Users/mario/Documents/Projects/intent-service/venv/lib/python3.9/site-packages/jobqueue_worker/services/azure_storage_helper.py", line 194, in queue_get
    return queue.receive_message(visibility_timeout=visibility_timeout)
  File "/Users/mario/Documents/Projects/intent-service/venv/lib/python3.9/site-packages/azure/core/tracing/decorator.py", line 73, in wrapper_use_tracer
    return func(*args, **kwargs)
  File "/Users/mario/Documents/Projects/intent-service/venv/lib/python3.9/site-packages/azure/storage/queue/_queue_client.py", line 538, in receive_message
    process_storage_error(error)
  File "/Users/mario/Documents/Projects/intent-service/venv/lib/python3.9/site-packages/azure/storage/queue/_shared/response_handlers.py", line 147, in process_storage_error
    raise error
azure.core.exceptions.ClientAuthenticationError: Server failed to authenticate the request. Make sure the value of Authorization header is formed correctly including the signature.
RequestId:d3c4286f-4003-0070-6f6d-471118000000
Time:2022-04-03T15:12:16.7153607Z
ErrorCode:AuthenticationFailed
Error:None
AuthenticationErrorDetail:Signed expiry time [Sat, 02 Apr 2022 23:21:47 GMT] has to be after signed start time [Sun, 03 Apr 2022 15:12:16 GMT]
Content: <?xml version="1.0" encoding="utf-8"?><Error><Code>AuthenticationFailed</Code><Message>Server failed to authenticate the request. Make sure the value of Authorization header is formed correctly including the signature.
RequestId:d3c4286f-4003-0070-6f6d-471118000000
Time:2022-04-03T15:12:16.7153607Z</Message><AuthenticationErrorDetail>Signed expiry time [Sat, 02 Apr 2022 23:21:47 GMT] has to be after signed start time [Sun, 03 Apr 2022 15:12:16 GMT]</AuthenticationErrorDetail></Error>
2022-04-03 17:12:16	jobqueue_worker	INFO	/Users/mario/Documents/Projects/intent-service/venv/lib/python3.9/site-packages/jobqueue_worker/worker.py|202	Retry backoff set to 900 seconds because 9 exception occured
2022-04-03 17:12:16	jobqueue_worker	INFO	/Users/mario/Documents/Projects/intent-service/venv/lib/python3.9/site-packages/jobqueue_worker/worker.py|287	retry wait: 900
